<?xml version="1.0" encoding="utf-8"?>
<!-- This URDF was automatically created by SolidWorks to URDF Exporter! Originally created by Stephen Brawner (brawner@gmail.com) 
     Commit Version: 1.6.0-4-g7f85cfe  Build Version: 1.6.7995.38578
     For more information, please see http://wiki.ros.org/sw_urdf_exporter -->
<robot
  name="QuadIP">
  <link
    name="BODY">
    <inertial>
      <origin
        xyz="0.00407 -0.00053 -0.00159"
        rpy="0 0 0" />
      <mass
        value="8.29295" />
      <inertia
        ixx="0.02567"
        ixy="0"
        ixz="0"
        iyy="0.1908"
        iyz="0"
        izz="0.20885" />
    </inertial>
  </link>
  <link
    name="FL_HP">
    <inertial>
      <origin
        xyz="-0.00958 0.00664 0.00176"
        rpy="0 0 0" />
      <mass
        value="1.2615" />
      <inertia
        ixx="0.00108"
        ixy="0"
        ixz="0"
        iyy="0.00166"
        iyz="0"
        izz="0.00176" />
    </inertial>
  </link>
  <joint
    name="1_FL_Roll"
    type="revolute">
    <origin
      xyz="0.27 0.055 0"
      rpy="0 0 0" />
    <parent
      link="BODY" />
    <child
      link="FL_HP" />
    <axis
      xyz="1 0 0" />
    <limit
      lower="-1"
      upper="1"
      effort="1000"
      velocity="0" />
  </joint>
  <link
    name="FL_THIGH">
    <inertial>
      <origin
        xyz="-0.0055 -0.02031 -0.03239"
        rpy="0 0 0" />
      <mass
        value="2.3269" />
      <inertia
        ixx="0.02004"
        ixy="0"
        ixz="0"
        iyy="0.01871"
        iyz="0"
        izz="0.00366" />
    </inertial>
  </link>
  <joint
    name="1_FL_Pitch"
    type="revolute">
    <origin
      xyz="0 0.1142 0"
      rpy="0 0 0" />
    <parent
      link="FL_HP" />
    <child
      link="FL_THIGH" />
    <axis
      xyz="0 1 0" />
    <limit
      lower="-3.14"
      upper="3.14"
      effort="1000"
      velocity="0" />
  </joint>
  <link
    name="FL_CALF">
    <inertial>
      <origin
        xyz="0.01134 6E-05 -0.15434"
        rpy="0 0 0" />
      <mass
        value="0.56128" />
      <inertia
        ixx="0.0262"
        ixy="0"
        ixz="0"
        iyy="0.02632"
        iyz="0"
        izz="0.0002" />
    </inertial>
  </link>
  <joint
    name="1_FL_Knee"
    type="revolute">
    <origin
      xyz="0 0 -0.28"
      rpy="0 0 0" />
    <parent
      link="FL_THIGH" />
    <child
      link="FL_CALF" />
    <axis
      xyz="0 1 0" />
    <limit
      lower="-3.14"
      upper="-0.17"
      effort="1000"
      velocity="0" />
  </joint>
  <link
    name="RL_HP">
    <inertial>
      <origin
        xyz="0.0096 0.0066 0.00016"
        rpy="0 0 0" />
      <mass
        value="1.259" />
      <inertia
        ixx="0.00108"
        ixy="0"
        ixz="0"
        iyy="0.00165"
        iyz="0"
        izz="0.00176" />
    </inertial>
  </link>
  <joint
    name="2_RL_Roll"
    type="revolute">
    <origin
      xyz="-0.27 0.055 0"
      rpy="0 0 0" />
    <parent
      link="BODY" />
    <child
      link="RL_HP" />
    <axis
      xyz="1 0 0" />
    <limit
      lower="-1"
      upper="1"
      effort="1000"
      velocity="0" />
  </joint>
  <link
    name="RL_THIGH">
    <inertial>
      <origin
        xyz="-0.0055 -0.02031 -0.03239"
        rpy="0 0 0" />
      <mass
        value="2.3269" />
      <inertia
        ixx="0.02004"
        ixy="0"
        ixz="0"
        iyy="0.01871"
        iyz="0"
        izz="0.00366" />
    </inertial>
  </link>
  <joint
    name="2_RL_Pitch"
    type="revolute">
    <origin
      xyz="0 0.1142 0"
      rpy="0 0 0" />
    <parent
      link="RL_HP" />
    <child
      link="RL_THIGH" />
    <axis
      xyz="0 1 0" />
    <limit
      lower="-3.14"
      upper="3.14"
      effort="1000"
      velocity="0" />
  </joint>
  <link
    name="RL_CALF">
    <inertial>
      <origin
        xyz="0.01134 6E-05 -0.15434"
        rpy="0 0 0" />
      <mass
        value="0.56128" />
      <inertia
        ixx="0.0262"
        ixy="0"
        ixz="0"
        iyy="0.02632"
        iyz="0"
        izz="0.0002" />
    </inertial>
  </link>
  <joint
    name="2_RL_Knee"
    type="revolute">
    <origin
      xyz="0 0 -0.28"
      rpy="0 0 0" />
    <parent
      link="RL_THIGH" />
    <child
      link="RL_CALF" />
    <axis
      xyz="0 1 0" />
    <limit
      lower="-3.14"
      upper="-0.17"
      effort="1000"
      velocity="0" />
  </joint>
  <link
    name="FR_HP">
    <inertial>
      <origin
        xyz="-0.0096 -0.0066 0.00016"
        rpy="0 0 0" />
      <mass
        value="1.259" />
      <inertia
        ixx="0.00108"
        ixy="0"
        ixz="0"
        iyy="0.00165"
        iyz="0"
        izz="0.00176" />
    </inertial>
  </link>
  <joint
    name="3_FR_Roll"
    type="revolute">
    <origin
      xyz="0.27 -0.055 0"
      rpy="0 0 0" />
    <parent
      link="BODY" />
    <child
      link="FR_HP" />
    <axis
      xyz="1 0 0" />
    <limit
      lower="-1"
      upper="1"
      effort="1000"
      velocity="0" />
  </joint>
  <link
    name="FR_THIGH">
    <inertial>
      <origin
        xyz="-0.0055 0.02031 -0.03246"
        rpy="0 0 0" />
      <mass
        value="2.32853" />
      <inertia
        ixx="0.02004"
        ixy="0"
        ixz="0"
        iyy="0.01872"
        iyz="0"
        izz="0.00366" />
    </inertial>
  </link>
  <joint
    name="3_FR_Pitch"
    type="revolute">
    <origin
      xyz="0 -0.1142 0"
      rpy="0 0 0" />
    <parent
      link="FR_HP" />
    <child
      link="FR_THIGH" />
    <axis
      xyz="0 1 0" />
    <limit
      lower="-3.14"
      upper="3.14"
      effort="1000"
      velocity="0" />
  </joint>
  <link
    name="FR_CALF">
    <inertial>
      <origin
        xyz="0.01134 6E-05 -0.15434"
        rpy="0 0 0" />
      <mass
        value="0.56128" />
      <inertia
        ixx="0.0262"
        ixy="0"
        ixz="0"
        iyy="0.02632"
        iyz="0"
        izz="0.0002" />
    </inertial>
  </link>
  <joint
    name="3_FR_Knee"
    type="revolute">
    <origin
      xyz="0 0 -0.28"
      rpy="0 0 0" />
    <parent
      link="FR_THIGH" />
    <child
      link="FR_CALF" />
    <axis
      xyz="0 1 0" />
    <limit
      lower="-3.14"
      upper="-0.17"
      effort="1000"
      velocity="0" />
  </joint>
  <link
    name="RR_HP">
    <inertial>
      <origin
        xyz="0.00958 -0.00664 -5E-05"
        rpy="0 0 0" />
      <mass
        value="1.2615" />
      <inertia
        ixx="0.00108"
        ixy="0"
        ixz="0"
        iyy="0.00166"
        iyz="0"
        izz="0.00176" />
    </inertial>
  </link>
  <joint
    name="4_RR_Roll"
    type="revolute">
    <origin
      xyz="-0.27 -0.055 0"
      rpy="0 0 0" />
    <parent
      link="BODY" />
    <child
      link="RR_HP" />
    <axis
      xyz="1 0 0" />
    <limit
      lower="-1"
      upper="1"
      effort="1000"
      velocity="0" />
  </joint>
  <link
    name="RR_THIGH">
    <inertial>
      <origin
        xyz="-0.0055 0.02031 -0.03246"
        rpy="0 0 0" />
      <mass
        value="2.32853" />
      <inertia
        ixx="0.02004"
        ixy="0"
        ixz="0"
        iyy="0.01872"
        iyz="0"
        izz="0.00366" />
    </inertial>
  </link>
  <joint
    name="4_RR_Pitch"
    type="revolute">
    <origin
      xyz="0 -0.1142 0"
      rpy="0 0 0" />
    <parent
      link="RR_HP" />
    <child
      link="RR_THIGH" />
    <axis
      xyz="0 1 0" />
    <limit
      lower="-3.14"
      upper="3.14"
      effort="1000"
      velocity="0" />
  </joint>
  <link
    name="RR_CALF">
    <inertial>
      <origin
        xyz="0.01134 6E-05 -0.15434"
        rpy="0 0 0" />
      <mass
        value="0.56128" />
      <inertia
        ixx="0.0262"
        ixy="0"
        ixz="0"
        iyy="0.02632"
        iyz="0"
        izz="0.0002" />
    </inertial>
  </link>
  <joint
    name="4_RR_Knee"
    type="revolute">
    <origin
      xyz="0 0 -0.28"
      rpy="0 0 0" />
    <parent
      link="RR_THIGH" />
    <child
      link="RR_CALF" />
    <axis
      xyz="0 1 0" />
    <limit
      lower="-3.14"
      upper="-0.17"
      effort="1000"
      velocity="0" />
  </joint>
</robot>
